Traceback (most recent call last):
  File "/opt/anaconda3/envs/codeforecon/lib/python3.8/site-packages/jupyter_cache/executors/utils.py", line 51, in single_nb_execution
    executenb(
  File "/opt/anaconda3/envs/codeforecon/lib/python3.8/site-packages/nbclient/client.py", line 1117, in execute
    return NotebookClient(nb=nb, resources=resources, km=km, **kwargs).execute()
  File "/opt/anaconda3/envs/codeforecon/lib/python3.8/site-packages/nbclient/util.py", line 78, in wrapped
    return just_run(coro(*args, **kwargs))
  File "/opt/anaconda3/envs/codeforecon/lib/python3.8/site-packages/nbclient/util.py", line 57, in just_run
    return loop.run_until_complete(coro)
  File "/opt/anaconda3/envs/codeforecon/lib/python3.8/asyncio/base_events.py", line 616, in run_until_complete
    return future.result()
  File "/opt/anaconda3/envs/codeforecon/lib/python3.8/site-packages/nbclient/client.py", line 558, in async_execute
    await self.async_execute_cell(
  File "/opt/anaconda3/envs/codeforecon/lib/python3.8/site-packages/nbclient/client.py", line 862, in async_execute_cell
    self._check_raise_for_error(cell, exec_reply)
  File "/opt/anaconda3/envs/codeforecon/lib/python3.8/site-packages/nbclient/client.py", line 765, in _check_raise_for_error
    raise CellExecutionError.from_cell_and_msg(cell, exec_reply_content)
nbclient.exceptions.CellExecutionError: An error occurred while executing the following cell:
------------------
# TODO: hide input
# Warning: This has a dependency on GraphViz
# On mac, using homebrew, brew install graphviz
import graphviz
import string

dot = graphviz.Digraph(comment="DAG example")
labels_list = ["Utilities", "Data Cleaning", "Analysis", "Generate Plots and Tables"]
names_list = string.ascii_uppercase[: len(labels_list)]
labels_to_names = dict(zip(labels_list, names_list))
for name, label in zip(names_list, labels_list):
    dot.node(name, label)

list_of_connections = [
    ("Utilities", "Data Cleaning"),
    ("Utilities", "Analysis"),
    ("Utilities", "Generate Plots and Tables"),
    ("Data Cleaning", "Analysis"),
    ("Analysis", "Generate Plots and Tables"),
]

list_of_connections = [
    (labels_to_names[a], labels_to_names[b]) for a, b in list_of_connections
]
dot.edges(list_of_connections)
dot
------------------

[0;31m---------------------------------------------------------------------------[0m
[0;31mModuleNotFoundError[0m                       Traceback (most recent call last)
[0;32m/var/folders/x6/ffnr59f116l96_y0q0bjfz7c0000gn/T/ipykernel_44949/2997369537.py[0m in [0;36m<module>[0;34m[0m
[1;32m      2[0m [0;31m# Warning: This has a dependency on GraphViz[0m[0;34m[0m[0;34m[0m[0;34m[0m[0m
[1;32m      3[0m [0;31m# On mac, using homebrew, brew install graphviz[0m[0;34m[0m[0;34m[0m[0;34m[0m[0m
[0;32m----> 4[0;31m [0;32mimport[0m [0mgraphviz[0m[0;34m[0m[0;34m[0m[0m
[0m[1;32m      5[0m [0;32mimport[0m [0mstring[0m[0;34m[0m[0;34m[0m[0m
[1;32m      6[0m [0;34m[0m[0m

[0;31mModuleNotFoundError[0m: No module named 'graphviz'
ModuleNotFoundError: No module named 'graphviz'

